<?xml version="1.0" ?>
<!-- =================================================================================== -->
<!-- |    This document was autogenerated by xacro from ur10_joint_limited_robot.urdf.xacro | -->
<!-- |    EDITING THIS FILE BY HAND IS NOT RECOMMENDED                                 | -->
<!-- =================================================================================== -->
<robot name="agv" xmlns:xacro="http://ros.org/wiki/xacro">
   <gazebo>
    <plugin name="gazebo_ros_control" filename="libgazebo_ros_control.so">
      <robotNamespace>/rrbot</robotNamespace>
      <robotSimType>gazebo_ros_control/DefaultRobotHWSim</robotSimType>
    </plugin>
  </gazebo>
  <!--
  Author: Kelsey Hawkins
  Contributers: Jimmy Da Silva, Ajit Krisshna N L, Muhammad Asif Rana
-->
  <!-- measured from model -->
<link name="world"/>
<joint name="world_joint" type="fixed">
  <parent link="world"/>
  <child link="agv_link_base"/>
  <origin rpy="0 0.0 0.0" xyz="0.0 0.0 0.0"/>
</joint>
<link name="agv_link_base"/>
<joint name="world_agv_joint_x" type="prismatic">
  <parent link="agv_link_base"/>
  <child link="agv_link_mid_1"/>
  <origin rpy="0.0 0.0 0.0" xyz="0.0 0.0 0.0"/>
  <axis xyz="1 0 0" />
  <limit effort="100.0" lower="-5" upper="5" velocity="1.0"/>
</joint>
<link name="agv_link_mid_1"/>
<joint name="world_agv_joint_y" type="prismatic">
  <parent link="agv_link_mid_1"/>
  <child link="agv_link_mid_2"/>
  <origin rpy="0.0 0.0 0.0" xyz="0.0 0.0 0.0"/>
  <axis xyz="0 1 0" />
  <limit effort="100.0" lower="-5" upper="5" velocity="1.0"/>
</joint>
<link name="agv_link_mid_2"/>
<joint name="world_agv_joint_z" type="continuous">
  <parent link="agv_link_mid_2"/>
  <child link="agv_link"/>
  <origin rpy="0.0 0.0 0.0" xyz="0.0 0.0 0.0"/>
  <axis xyz="0 0 1" />  
  <!-- <limit effort="999.0" velocity="1.0"/> -->
</joint>
<link name="agv_link">
    <visual>
      <geometry>
        <mesh filename="package://agv_description/meshes/agv_base/agv_center.STL"/>
      </geometry>
      <material name="Blue">
        <color rgba="0.5 0.5 0.8 1.0"/>
      </material>
    </visual>
    <collision>
      <geometry>
        <mesh filename="package://agv_description/meshes/agv_base/agv_center.STL"/>
      </geometry>
    </collision>
    <!-- <inertial>
      <mass value="4.0"/>
      <origin rpy="0 0 0" xyz="0.0 0.0 0.0"/>
      <inertia ixx="0.0061063308908" ixy="0.0" ixz="0.0" iyy="0.0061063308908" iyz="0.0" izz="0.01125"/>
    </inertial> -->
  </link>

<joint name="world_charge_base_joint" type="fixed">
  <parent link="world"/>
  <child link="charge_base_link"/>
  <origin rpy="1.5707963267949 0.0 0.0" xyz="0.0 0.0 0.0"/>
</joint>
<link name="charge_base_link">
    <visual>
      <geometry>
        <mesh filename="package://agv_description/meshes/agv_base/base.STL"/>
      </geometry>
      <material name="LightGrey">
        <color rgba="0.7 0.7 0.7 1.0"/>
      </material>
    </visual>
    <collision>
      <geometry>
        <mesh filename="package://agv_description/meshes/agv_base/base.STL"/>
      </geometry>
    </collision>
 </link>
<!--   <transmission name="agv_link">
    <type>transmission_interface/SimpleTransmission</type>
    <joint name="agv_link">
      <hardwareInterface>hardware_interface/PositionJointInterface</hardwareInterface>
    </joint>
    <actuator name="agv_link">
      <mechanicalReduction>1</mechanicalReduction>
    </actuator>
  </transmission> -->

  <gazebo reference="agv_link">
    <mu1>0.2</mu1>
    <mu2>0.2</mu2>
    <!-- <selfCollide>true</selfCollide> -->
    <material>Gazebo/Orange</material>
  </gazebo>

</robot>

